Workbook

Sheet Start Here
B2: Bank Reconciliation Workbook
B3: Standard layout for matching bank activity to the general ledger, one bank account per workbook.
B5: Monthly workflow
B6: 1. Config: enter client, period dates, statement ending balance and GL ending balance.
B7: 2. Paste the raw bank export onto 'Bank Raw' and the raw GL detail onto 'GL Raw', exactly as downloaded.
B8: 3. Import: raw rows are normalized into 'Bank' and 'GL' using the Config import map (done by the bank-rec-match skill, or by hand).
B9: 4. Match: run the skill. It shows a dry run first, then marks Status / Match Type / Matched ID and refreshes 'Pairs' and 'Open Items'.
B10: 5. Review: work the yellow (Amount-only) and pink (Near) rows. Decisions are recorded in the columns, not by recoloring.
B11: 6. Rec tab: 'Unexplained difference' must be 0.00 and every check must read OK before sign-off.
B12: 7. Next month: Save As, delete Status = Y rows from Bank and GL, clear raw tabs, update Config. Open items carry forward with their IDs.
B14: Match types and colors (Match Type column drives the color, never paint cells by hand)
B15: Match Type | C15: Status | D15: Meaning
B16: Exact | C16: Y | D16: Amount exact and descriptions agree (check #, vendor/customer name, or known alias).
B17: Amount-only | C17: Y | D17: Amount exact, descriptions share nothing. Reconciled, but an accountant must review the note.
B18: Near | C18: blank | D18: Amounts 1-10 cents apart. NOT reconciled. Review Note names the candidate ID on the other side.
B19: Tolerance | C19: Y | D19: Only if enabled in Config for listed keywords. Reconciled; cents difference needs an adjusting entry.
B20: Manual | C20: Y | D20: Paired by a person. Set Status, Match Type and Matched ID on both sides.
B21: (blank) | C21: blank | D21: No match. Stays open and flows to the Open Items tab.
B23: Cell legend
B24: Input | C24: Pale green with blue text: type here (Config, and the ID columns on Pairs / Open Items that the skill fills).
B25: Formula | C25: Grey header: formula column. Do not type over it. Rec, Pairs and Open Items are formulas throughout.
B27: Bank and GL tabs: the standard row (both tabs use identical columns)
B28: ID | C28: Date | D28: Description | E28: Ref / Check # | F28: Amount | G28: Status | H28: Match Type | I28: Matched ID | J28: Review Note | K28: Pass
B29: G-2608-0001 | C29: 46236 | D29: Summit Fleet Repair - Truck repair | E29: 1045 | F29: -1250 | G29: Y | H29: Exact | I29: B-2608-0001 | K29: 1
B30: Example row only (not part of the rec). The 11th column, Raw Row, records which raw-tab row the line came from.
B32: Rules
B33: • Amount is ONE signed column from the cash account's view: money in is positive, money out is negative, on both tabs.
B34: • IDs never change. Format B-YYMM-#### (bank) and G-YYMM-#### (GL). Carried-forward items keep their original ID, so their age shows.
B35: • Matching is one-to-one. One bank row pairs with one GL row. Batched deposits (one deposit = several receipts) are not handled yet.
B36: • Bank tab: statement period activity plus open bank items carried from last month. GL tab: activity through period end plus open GL items carried.
B37: • Undo a pass: filter Pass = n on both tabs, clear Status, Match Type, Matched ID, Review Note and Pass, then refresh Pairs and Open Items.
B38: • Sorting and filtering Bank / GL is always safe. Everything links by ID, not by row number.

Sheet Rec
B2: Bank Reconciliation
B3: =IF(CFG_Client="","Client not set in Config",CFG_Client&" | "&CFG_Bank&" x"&CFG_Acct&" | GL "&CFG_GLAcct) -> Sample Landscaping LLC (fictional) | First Example Bank x4821 | GL 1010 Operating Cash
B4: =IF(CFG_PeriodEnd="","Period end not set in Config","Period ending "&TEXT(CFG_PeriodEnd,"mmmm d, yyyy")) -> Period ending August 31, 2026
B6: 1. Balance reconciliation
B7: Balance per bank statement | D7: =CFG_BankBal -> 20315.03
B8: Add: deposits in transit (in GL, not yet on bank) | D8: =SUMIFS(GL!$E:$E,GL!$F:$F,"<>Y",GL!$E:$E,">0") -> 960
B9: Less: outstanding checks and payments (in GL, not yet on bank) | D9: =SUMIFS(GL!$E:$E,GL!$F:$F,"<>Y",GL!$E:$E,"<0") -> -3030.95
B10: Adjusted bank balance | D10: =SUM(D7:D9) -> 18244.08
B12: Balance per GL | D12: =CFG_GLBal -> 18452.19
B13: Add: bank credits not yet in GL (deposits, interest) | D13: =SUMIFS(Bank!$E:$E,Bank!$F:$F,"<>Y",Bank!$E:$E,">0") -> 3.12
B14: Less: bank debits not yet in GL (fees, drafts) | D14: =SUMIFS(Bank!$E:$E,Bank!$F:$F,"<>Y",Bank!$E:$E,"<0") -> -211.23
B15: Adjusted book balance | D15: =SUM(D12:D14) -> 18244.08
B17: Difference (adjusted bank less adjusted book) | D17: =D10-D15 -> 0
B18: Less: cents differences accepted on reconciled pairs (needs adjusting entry) | D18: =C24-D24 -> 0
B19: Unexplained difference | D19: =ROUND(D17-D18,2) -> 0
B20: Status | D20: =IF(OR(CFG_BankBal="",CFG_GLBal=""),"ENTER BALANCES IN CONFIG",IF(ABS(D19)<0.005,"RECONCILED","NOT RECONCILED")) -> RECONCILED
B22: 2. Matching checks (all must read OK)
B23: Check | C23: Bank | D23: GL | E23: Expected | F23: Result
B24: Reconciled total (Status = Y) | C24: =SUMIFS(Bank!$E:$E,Bank!$F:$F,"Y") -> -2747.65 | D24: =SUMIFS(GL!$E:$E,GL!$F:$F,"Y") -> -2747.65 | E24: Bank less GL = Pairs difference | F24: =IF(ABS((C24-D24)-Pairs!$E$3)<0.005,"OK","CHECK") -> OK
B25: Reconciled count (Status = Y) | C25: =COUNTIFS(Bank!$F:$F,"Y") -> 12 | D25: =COUNTIFS(GL!$F:$F,"Y") -> 12 | E25: Equal (one-to-one) | F25: =IF(C25=D25,"OK","CHECK") -> OK
B26: Pairs listed on Pairs tab | C26: =COUNTIF(Pairs!$A$6:$A$2005,"?*") -> 12 | E26: Equals reconciled count | F26: =IF(C26=C25,"OK","REFRESH PAIRS") -> OK
B27: Pair link problems | C27: =Pairs!$H$3 -> 0 | E27: 0 | F27: =IF(C27=0,"OK","CHECK PAIRS") -> OK
B28: Status = Y with no Matched ID | C28: =COUNTIFS(Bank!$F:$F,"Y",Bank!$H:$H,"") -> 0 | D28: =COUNTIFS(GL!$F:$F,"Y",GL!$H:$H,"") -> 0 | E28: 0 | F28: =IF(AND(C28=0,D28=0),"OK","CHECK") -> OK
B29: Near items marked Y | C29: =COUNTIFS(Bank!$G:$G,"Near",Bank!$F:$F,"Y") -> 0 | D29: =COUNTIFS(GL!$G:$G,"Near",GL!$F:$F,"Y") -> 0 | E29: 0 | F29: =IF(AND(C29=0,D29=0),"OK","CHECK") -> OK
B30: Rows whose Amount is not a number | C30: =COUNTIFS(Bank!$A:$A,"?*")-1-COUNT(Bank!$E:$E) -> 0 | D30: =COUNTIFS(GL!$A:$A,"?*")-1-COUNT(GL!$E:$E) -> 0 | E30: 0 | F30: =IF(AND(C30=0,D30=0),"OK","CHECK") -> OK
B31: Rows dated after period end | C31: =IF(CFG_PeriodEnd="",0,COUNTIFS(Bank!$B:$B,">"&CFG_PeriodEnd)) -> 0 | D31: =IF(CFG_PeriodEnd="",0,COUNTIFS(GL!$B:$B,">"&CFG_PeriodEnd)) -> 0 | E31: 0 | F31: =IF(AND(C31=0,D31=0),"OK","CHECK") -> OK
B32: Open Items list vs tabs (difference) | C32: =ROUND(SUMIFS('Open Items'!$G$6:$G$2005,'Open Items'!$A$6:$A$2005,"Bank")-(D13+D14),2) -> 0 | D32: =ROUND(SUMIFS('Open Items'!$G$6:$G$2005,'Open Items'!$A$6:$A$2005,"GL")-(D8+D9),2) -> 0 | E32: 0 | F32: =IF(AND(C32=0,D32=0),"OK","REFRESH OPEN ITEMS") -> OK
B33: All checks | F33: =IF(COUNTIF(F24:F32,"OK")=9,"ALL OK","SEE ABOVE") -> ALL OK
B35: 3. Review queue
B36: Match Type | C36: Bank | D36: GL | E36: Action
B37: Exact | C37: =COUNTIFS(Bank!$G:$G,"Exact") -> 11 | D37: =COUNTIFS(GL!$G:$G,"Exact") -> 11 | E37: None.
B38: Amount-only (yellow) | C38: =COUNTIFS(Bank!$G:$G,"Amount-only") -> 1 | D38: =COUNTIFS(GL!$G:$G,"Amount-only") -> 1 | E38: Read the Review Note. Unpair if wrong.
B39: Near (pink) | C39: =COUNTIFS(Bank!$G:$G,"Near") -> 1 | D39: =COUNTIFS(GL!$G:$G,"Near") -> 1 | E39: Decide: pair as Manual, or leave open.
B40: Tolerance (lavender) | C40: =COUNTIFS(Bank!$G:$G,"Tolerance") -> 0 | D40: =COUNTIFS(GL!$G:$G,"Tolerance") -> 0 | E40: Book the cents adjustment.
B41: Manual | C41: =COUNTIFS(Bank!$G:$G,"Manual") -> 0 | D41: =COUNTIFS(GL!$G:$G,"Manual") -> 0 | E41: None.
B42: Open, no candidate | C42: =COUNTIFS(Bank!$A:$A,"?*",Bank!$F:$F,"<>Y",Bank!$G:$G,"") -> 2 | D42: =COUNTIFS(GL!$A:$A,"?*",GL!$F:$F,"<>Y",GL!$G:$G,"") -> 4 | E42: Research, or leave as reconciling item.
B43: Total rows | C43: =COUNTIFS(Bank!$A:$A,"?*")-1 -> 15 | D43: =COUNTIFS(GL!$A:$A,"?*")-1 -> 17
B45: 4. Sign-off
B46: Prepared by | C46: =IF(CFG_Preparer="","",CFG_Preparer) -> S. Milovanov | D46: =IF(CFG_PrepDate="","",CFG_PrepDate) -> 46269
B47: Reviewed by | C47: =IF(CFG_Reviewer="","",CFG_Reviewer) | D47: =IF(CFG_RevDate="","",CFG_RevDate)
...

Sheet Config
B1: Config: client settings
B2: Pale green cells are inputs. Every other tab reads from here.
B4: Client and period
B5: Client name | C5: Sample Landscaping LLC (fictional)
B6: Bank name | C6: First Example Bank
B7: Bank account (last 4) | C7: 4821 | E7: Last four digits only.
B8: GL cash account | C8: 1010 Operating Cash | E8: Number and name, e.g. 1010 Operating Cash.
B9: Period start | C9: 46235
B10: Period end | C10: 46265 | E10: Statement end date.
B11: Balance per bank statement (period end) | C11: 20315.03 | E11: From the statement, not the export.
B12: Balance per GL (period end) | C12: 18452.19 | E12: From the trial balance / GL report.
B13: Prepared by | C13: S. Milovanov
B14: Date prepared | C14: 46269
B15: Reviewed by
B16: Date reviewed
B18: Matching rules
B19: Near-match minimum difference | C19: 0.01 | E19: Default 0.01.
B20: Near-match maximum difference | C20: 0.1 | E20: Default 0.10. Near matches are note-only unless the keyword rule below says otherwise.
B21: Days bank may post BEFORE the GL date | C21: 3 | E21: Applies to every match except check-number matches.
B22: Days bank may post AFTER the GL date (non-check) | C22: 7 | E22: ACH, card, transfers, deposits.
B23: Days bank may post AFTER the GL date (checks) | C23: 90 | E23: Checks clear late. Check-number matches ignore the window entirely.
B24: Near matches on tolerance keywords | C24: Note only | E24: 'Note only' (default) or 'Reconcile as Tolerance'.
B25: Tolerance keywords (comma-separated) | E25: e.g. PAYROLL, GENERAC. Whole word, case-insensitive, must appear on BOTH sides.
B27: Raw import map (fill once per client; the import reuses it every month)
B28: Setting | C28: Bank Raw | D28: GL Raw | E28: Notes
B29: Header row number | C29: 1 | D29: 1 | E29: Row the column headers sit on.
B30: Date column | C30: A | D30: A | E30: Column letter, e.g. A.
B31: Description column(s) | C31: B | D31: C,D | E31: One letter, or several joined with ' - ' (e.g. D,E for Name - Memo).
B32: Reference / check # column | C32: C | D32: B | E32: Leave blank if check numbers only appear in the description.
B33: Amount layout | C33: Separate in / out columns | D33: Separate in / out columns | E33: 'Single signed column' or 'Separate in / out columns'.
B34: Amount column (single layout)
B35: Money-in column (bank credits / GL debits) | C35: E | D35: E | E35: Separate layout only.
B36: Money-out column (bank debits / GL credits) | C36: D | D36: F | E36: Separate layout only. Values may be shown positive.
B37: In single layout, money out is shown as | E37: 'Negative' or 'Positive'. If Positive, the import flips the sign.
B38: Date format in raw file | C38: M/D/Y | D38: M/D/Y | E38: 'Auto', 'M/D/Y' or 'D/M/Y'.
B39: Footer rows to skip (totals, balances) | C39: 0 | D39: 0 | E39: Number of rows at the bottom to ignore.
B41: Aliases (bank wording that means the same party as GL wording)
B42: Bank text contains | C42: GL text contains | D42: Note
B43: ROCKY MTN POWER | C43: Rocky Mountain Power | D43: Utility abbreviation
B44: SAV 7732 | C44: Savings x7732 | D44: Internal transfer

Sheet Bank
A1: ID | B1: Date | C1: Description | D1: Ref / Check # | E1: Amount | F1: Status | G1: Match Type | H1: Matched ID | I1: Review Note | J1: Pass | K1: Raw Row
A2: B-2608-0001 | B2: 46237 | C2: CHECK 1045 | D2: 1045 | E2: -1250 | F2: Y | G2: Exact | H2: G-2608-0001 | J2: 1 | K2: 2
A3: B-2608-0002 | B3: 46238 | C3: DEPOSIT | E3: 4380 | F3: Y | G3: Amount-only | H3: G-2608-0002 | I3: Accountant review: amount-only match. Bank: "DEPOSIT" | GL: "Hillside HOA - Customer payment" | J3: 1 | K3: 3
A4: B-2608-0003 | B4: 46239 | C4: ACH DEBIT ADP PAYROLL 080526 | E4: -8912.44 | F4: Y | G4: Exact | H4: G-2608-0004 | J4: 1 | K4: 4
A5: B-2608-0004 | B5: 46240 | C5: CHECK 1047 | D5: 1047 | E5: -1250 | F5: Y | G5: Exact | H5: G-2608-0003 | J5: 1 | K5: 5
A6: B-2608-0005 | B6: 46241 | C6: POS PURCHASE HOME DEPOT #4410 | E6: -612.87 | F6: Y | G6: Exact | H6: G-2608-0005 | J6: 1 | K6: 6
A7: B-2608-0006 | B7: 46244 | C7: ONLINE TRANSFER FROM SAV 7732 | E7: 5000 | F7: Y | G7: Exact | H7: G-2608-0006 | J7: 1 | K7: 7
A8: B-2608-0007 | B8: 46246 | C8: ACH DEBIT ROCKY MTN POWER | E8: -318.4 | F8: Y | G8: Exact | H8: G-2608-0007 | J8: 1 | K8: 8
A9: B-2608-0008 | B9: 46248 | C9: CHECK 1038 | D9: 1038 | E9: -2000 | F9: Y | G9: Exact | H9: G-2607-0019 | J9: 1 | K9: 9
A10: B-2608-0009 | B10: 46251 | C10: MOBILE DEPOSIT ALVAREZ | E10: 1215.5 | F10: Y | G10: Exact | H10: G-2608-0009 | J10: 1 | K10: 10
A11: B-2608-0010 | B11: 46253 | C11: ACH DEBIT VERIZON WIRELESS | E11: -186.23 | G11: Near | I11: Near match: GL G-2608-0010 "Verizon Wireless - August" -186.20 (diff 0.03). Not reconciled. | J11: 1 | K11: 11
A12: B-2608-0011 | B12: 46255 | C12: CHECK 1046 | D12: 1046 | E12: -743.1 | F12: Y | G12: Exact | H12: G-2608-0008 | J12: 1 | K12: 12
A13: B-2608-0012 | B13: 46258 | C13: ACH CREDIT STRIPE TRANSFER | E13: 2847.66 | F13: Y | G13: Exact | H13: G-2608-0011 | J13: 1 | K13: 13
A14: B-2608-0013 | B14: 46260 | C14: ACH DEBIT UTAH STATE TAX | E14: -1104 | F14: Y | G14: Exact | H14: G-2608-0012 | J14: 1 | K14: 14
A15: B-2608-0014 | B15: 46263 | C15: SERVICE CHARGE | E15: -25 | K15: 15
A16: B-2608-0015 | B16: 46265 | C16: INTEREST PAYMENT | E16: 3.12 | K16: 16

Sheet GL
A1: ID | B1: Date | C1: Description | D1: Ref / Check # | E1: Amount | F1: Status | G1: Match Type | H1: Matched ID | I1: Review Note | J1: Pass | K1: Raw Row
A2: G-2607-0019 | B2: 46231 | C2: Canyon Properties - Aug rent | D2: 1038 | E2: -2000 | F2: Y | G2: Exact | H2: B-2608-0008 | J2: 1 | K2: Carried from 2607
A3: G-2607-0022 | B3: 46233 | C3: Wasatch Tree Supply - Saplings | D3: 1041 | E3: -455 | K3: Carried from 2607
A4: G-2608-0001 | B4: 46236 | C4: Summit Fleet Repair - Truck repair | D4: 1045 | E4: -1250 | F4: Y | G4: Exact | H4: B-2608-0001 | J4: 1 | K4: 2
A5: G-2608-0002 | B5: 46237 | C5: Hillside HOA - Customer payment | E5: 4380 | F5: Y | G5: Amount-only | H5: B-2608-0002 | I5: Accountant review: amount-only match. Bank: "DEPOSIT" | GL: "Hillside HOA - Customer payment" | J5: 1 | K5: 3
A6: G-2608-0003 | B6: 46238 | C6: Granite Equipment Rental - Skid steer | D6: 1047 | E6: -1250 | F6: Y | G6: Exact | H6: B-2608-0004 | J6: 1 | K6: 4
A7: G-2608-0004 | B7: 46239 | C7: ADP - Payroll 8/5 | E7: -8912.44 | F7: Y | G7: Exact | H7: B-2608-0003 | J7: 1 | K7: 5
A8: G-2608-0005 | B8: 46241 | C8: Home Depot - Irrigation parts | E8: -612.87 | F8: Y | G8: Exact | H8: B-2608-0005 | J8: 1 | K8: 6
A9: G-2608-0006 | B9: 46244 | C9: Savings x7732 - Transfer in | E9: 5000 | F9: Y | G9: Exact | H9: B-2608-0006 | J9: 1 | K9: 7
A10: G-2608-0007 | B10: 46245 | C10: Rocky Mountain Power - August service | E10: -318.4 | F10: Y | G10: Exact | H10: B-2608-0007 | J10: 1 | K10: 8
A11: G-2608-0008 | B11: 46246 | C11: Alpine Nursery - Plants | D11: 1046 | E11: -743.1 | F11: Y | G11: Exact | H11: B-2608-0011 | J11: 1 | K11: 9
A12: G-2608-0009 | B12: 46249 | C12: J. Alvarez - Mobile deposit inv 2291 | E12: 1215.5 | F12: Y | G12: Exact | H12: B-2608-0009 | J12: 1 | K12: 10
A13: G-2608-0010 | B13: 46252 | C13: Verizon Wireless - August | E13: -186.2 | G13: Near | I13: Near match: Bank B-2608-0010 "ACH DEBIT VERIZON WIRELESS" -186.23 (diff 0.03). Not reconciled. | J13: 1 | K13: 11
A14: G-2608-0011 | B14: 46258 | C14: Stripe - Payout 8/24 | E14: 2847.66 | F14: Y | G14: Exact | H14: B-2608-0012 | J14: 1 | K14: 12
A15: G-2608-0012 | B15: 46260 | C15: Utah State Tax Commission - Withholding | E15: -1104 | F15: Y | G15: Exact | H15: B-2608-0013 | J15: 1 | K15: 13
A16: G-2608-0013 | B16: 46262 | C16: Canyon Properties - Sep rent | D16: 1049 | E16: -2000 | K16: 14
A17: G-2608-0014 | B17: 46263 | C17: Peak Fuel - Fuel | D17: 1050 | E17: -389.75 | K17: 15
A18: G-2608-0015 | B18: 46265 | C18: Birch Lane Homes - Customer payment | E18: 960 | K18: 16

Sheet Pairs
A1: Reconciled pairs
A2: The skill writes Bank IDs into column A (all Status = Y bank rows). Every other column is a formula that follows the IDs.
A3: Pairs listed | B3: =COUNTIF(A6:A2005,"?*") -> 12 | D3: Total difference | E3: =SUM(M6:M2005) -> 0 | G3: Link problems | H3: =COUNTIF(N6:N2005,"BROKEN*")+COUNTIF(N6:N2005,"NOT FOUND*") -> 0
A5: Bank ID | B5: bank row | C5: Match Type | D5: Pass | E5: Bank Date | F5: Bank Description | G5: Bank Amount | H5: GL ID | I5: gl row | J5: GL Date | K5: GL Description | L5: GL Amount | M5: Difference | N5: Link Check
A6: B-2608-0001 | B6: =IF(A6="",0,IFERROR(MATCH(A6,Bank!$A:$A,0),0)) -> 2 | C6: =IF(B6=0,"",IF(INDEX(Bank!$G:$G,B6)="","",INDEX(Bank!$G:$G,B6))) -> Exact | D6: =IF(B6=0,"",IF(INDEX(Bank!$J:$J,B6)="","",INDEX(Bank!$J:$J,B6))) -> 1 | E6: =IF(B6=0,"",INDEX(Bank!$B:$B,B6)) -> 46237 | F6: =IF(B6=0,"",IF(INDEX(Bank!$C:$C,B6)="","",INDEX(Bank!$C:$C,B6))) -> CHECK 1045 | G6: =IF(B6=0,"",INDEX(Bank!$E:$E,B6)) -> -1250 | H6: =IF(B6=0,"",IF(INDEX(Bank!$H:$H,B6)="","",INDEX(Bank!$H:$H,B6))) -> G-2608-0001 | I6: =IF(H6="",0,IFERROR(MATCH(H6,GL!$A:$A,0),0)) -> 4 | J6: =IF(I6=0,"",INDEX(GL!$B:$B,I6)) -> 46236 | K6: =IF(I6=0,"",IF(INDEX(GL!$C:$C,I6)="","",INDEX(GL!$C:$C,I6))) -> Summit Fleet Repair - Truck repair | L6: =IF(I6=0,"",INDEX(GL!$E:$E,I6)) -> -1250 | M6: =IF(OR(B6=0,I6=0),"",ROUND(G6-L6,2)) -> 0 | N6: =IF(A6="","",IF(B6=0,"NOT FOUND: bank ID",IF(I6=0,"NOT FOUND: GL ID",IF(INDEX(GL!$H:$H,I6)<>A6,"BROKEN: GL points elsewhere",IF(OR(INDEX(Bank!$F:$F,B6)<>"Y",INDEX(GL!$F:$F,I6)<>"Y"),"BROKEN: Status not Y","OK"))))) -> OK
A7: B-2608-0002 | B7: =IF(A7="",0,IFERROR(MATCH(A7,Bank!$A:$A,0),0)) -> 3 | C7: =IF(B7=0,"",IF(INDEX(Bank!$G:$G,B7)="","",INDEX(Bank!$G:$G,B7))) -> Amount-only | D7: =IF(B7=0,"",IF(INDEX(Bank!$J:$J,B7)="","",INDEX(Bank!$J:$J,B7))) -> 1 | E7: =IF(B7=0,"",INDEX(Bank!$B:$B,B7)) -> 46238 | F7: =IF(B7=0,"",IF(INDEX(Bank!$C:$C,B7)="","",INDEX(Bank!$C:$C,B7))) -> DEPOSIT | G7: =IF(B7=0,"",INDEX(Bank!$E:$E,B7)) -> 4380 | H7: =IF(B7=0,"",IF(INDEX(Bank!$H:$H,B7)="","",INDEX(Bank!$H:$H,B7))) -> G-2608-0002 | I7: =IF(H7="",0,IFERROR(MATCH(H7,GL!$A:$A,0),0)) -> 5 | J7: =IF(I7=0,"",INDEX(GL!$B:$B,I7)) -> 46237 | K7: =IF(I7=0,"",IF(INDEX(GL!$C:$C,I7)="","",INDEX(GL!$C:$C,I7))) -> Hillside HOA - Customer payment | L7: =IF(I7=0,"",INDEX(GL!$E:$E,I7)) -> 4380 | M7: =IF(OR(B7=0,I7=0),"",ROUND(G7-L7,2)) -> 0 | N7: =IF(A7="","",IF(B7=0,"NOT FOUND: bank ID",IF(I7=0,"NOT FOUND: GL ID",IF(INDEX(GL!$H:$H,I7)<>A7,"BROKEN: GL points elsewhere",IF(OR(INDEX(Bank!$F:$F,B7)<>"Y",INDEX(GL!$F:$F,I7)<>"Y"),"BROKEN: Status not Y","OK"))))) -> OK
A8: B-2608-0003 | B8: =IF(A8="",0,IFERROR(MATCH(A8,Bank!$A:$A,0),0)) -> 4 | C8: =IF(B8=0,"",IF(INDEX(Bank!$G:$G,B8)="","",INDEX(Bank!$G:$G,B8))) -> Exact | D8: =IF(B8=0,"",IF(INDEX(Bank!$J:$J,B8)="","",INDEX(Bank!$J:$J,B8))) -> 1 | E8: =IF(B8=0,"",INDEX(Bank!$B:$B,B8)) -> 46239 | F8: =IF(B8=0,"",IF(INDEX(Bank!$C:$C,B8)="","",INDEX(Bank!$C:$C,B8))) -> ACH DEBIT ADP PAYROLL 080526 | G8: =IF(B8=0,"",INDEX(Bank!$E:$E,B8)) -> -8912.44 | H8: =IF(B8=0,"",IF(INDEX(Bank!$H:$H,B8)="","",INDEX(Bank!$H:$H,B8))) -> G-2608-0004 | I8: =IF(H8="",0,IFERROR(MATCH(H8,GL!$A:$A,0),0)) -> 7 | J8: =IF(I8=0,"",INDEX(GL!$B:$B,I8)) -> 46239 | K8: =IF(I8=0,"",IF(INDEX(GL!$C:$C,I8)="","",INDEX(GL!$C:$C,I8))) -> ADP - Payroll 8/5 | L8: =IF(I8=0,"",INDEX(GL!$E:$E,I8)) -> -8912.44 | M8: =IF(OR(B8=0,I8=0),"",ROUND(G8-L8,2)) -> 0 | N8: =IF(A8="","",IF(B8=0,"NOT FOUND: bank ID",IF(I8=0,"NOT FOUND: GL ID",IF(INDEX(GL!$H:$H,I8)<>A8,"BROKEN: GL points elsewhere",IF(OR(INDEX(Bank!$F:$F,B8)<>"Y",INDEX(GL!$F:$F,I8)<>"Y"),"BROKEN: Status not Y","OK"))))) -> OK
A9: B-2608-0004 | B9: =IF(A9="",0,IFERROR(MATCH(A9,Bank!$A:$A,0),0)) -> 5 | C9: =IF(B9=0,"",IF(INDEX(Bank!$G:$G,B9)="","",INDEX(Bank!$G:$G,B9))) -> Exact | D9: =IF(B9=0,"",IF(INDEX(Bank!$J:$J,B9)="","",INDEX(Bank!$J:$J,B9))) -> 1 | E9: =IF(B9=0,"",INDEX(Bank!$B:$B,B9)) -> 46240 | F9: =IF(B9=0,"",IF(INDEX(Bank!$C:$C,B9)="","",INDEX(Bank!$C:$C,B9))) -> CHECK 1047 | G9: =IF(B9=0,"",INDEX(Bank!$E:$E,B9)) -> -1250 | H9: =IF(B9=0,"",IF(INDEX(Bank!$H:$H,B9)="","",INDEX(Bank!$H:$H,B9))) -> G-2608-0003 | I9: =IF(H9="",0,IFERROR(MATCH(H9,GL!$A:$A,0),0)) -> 6 | J9: =IF(I9=0,"",INDEX(GL!$B:$B,I9)) -> 46238 | K9: =IF(I9=0,"",IF(INDEX(GL!$C:$C,I9)="","",INDEX(GL!$C:$C,I9))) -> Granite Equipment Rental - Skid steer | L9: =IF(I9=0,"",INDEX(GL!$E:$E,I9)) -> -1250 | M9: =IF(OR(B9=0,I9=0),"",ROUND(G9-L9,2)) -> 0 | N9: =IF(A9="","",IF(B9=0,"NOT FOUND: bank ID",IF(I9=0,"NOT FOUND: GL ID",IF(INDEX(GL!$H:$H,I9)<>A9,"BROKEN: GL points elsewhere",IF(OR(INDEX(Bank!$F:$F,B9)<>"Y",INDEX(GL!$F:$F,I9)<>"Y"),"BROKEN: Status not Y","OK"))))) -> OK
A10: B-2608-0005 | B10: =IF(A10="",0,IFERROR(MATCH(A10,Bank!$A:$A,0),0)) -> 6 | C10: =IF(B10=0,"",IF(INDEX(Bank!$G:$G,B10)="","",INDEX(Bank!$G:$G,B10))) -> Exact | D10: =IF(B10=0,"",IF(INDEX(Bank!$J:$J,B10)="","",INDEX(Bank!$J:$J,B10))) -> 1 | E10: =IF(B10=0,"",INDEX(Bank!$B:$B,B10)) -> 46241 | F10: =IF(B10=0,"",IF(INDEX(Bank!$C:$C,B10)="","",INDEX(Bank!$C:$C,B10))) -> POS PURCHASE HOME DEPOT #4410 | G10: =IF(B10=0,"",INDEX(Bank!$E:$E,B10)) -> -612.87 | H10: =IF(B10=0,"",IF(INDEX(Bank!$H:$H,B10)="","",INDEX(Bank!$H:$H,B10))) -> G-2608-0005 | I10: =IF(H10="",0,IFERROR(MATCH(H10,GL!$A:$A,0),0)) -> 8 | J10: =IF(I10=0,"",INDEX(GL!$B:$B,I10)) -> 46241 | K10: =IF(I10=0,"",IF(INDEX(GL!$C:$C,I10)="","",INDEX(GL!$C:$C,I10))) -> Home Depot - Irrigation parts | L10: =IF(I10=0,"",INDEX(GL!$E:$E,I10)) -> -612.87 | M10: =IF(OR(B10=0,I10=0),"",ROUND(G10-L10,2)) -> 0 | N10: =IF(A10="","",IF(B10=0,"NOT FOUND: bank ID",IF(I10=0,"NOT FOUND: GL ID",IF(INDEX(GL!$H:$H,I10)<>A10,"BROKEN: GL points elsewhere",IF(OR(INDEX(Bank!$F:$F,B10)<>"Y",INDEX(GL!$F:$F,I10)<>"Y"),"BROKEN: Status not Y","OK"))))) -> OK
A11: B-2608-0006 | B11: =IF(A11="",0,IFERROR(MATCH(A11,Bank!$A:$A,0),0)) -> 7 | C11: =IF(B11=0,"",IF(INDEX(Bank!$G:$G,B11)="","",INDEX(Bank!$G:$G,B11))) -> Exact | D11: =IF(B11=0,"",IF(INDEX(Bank!$J:$J,B11)="","",INDEX(Bank!$J:$J,B11))) -> 1 | E11: =IF(B11=0,"",INDEX(Bank!$B:$B,B11)) -> 46244 | F11: =IF(B11=0,"",IF(INDEX(Bank!$C:$C,B11)="","",INDEX(Bank!$C:$C,B11))) -> ONLINE TRANSFER FROM SAV 7732 | G11: =IF(B11=0,"",INDEX(Bank!$E:$E,B11)) -> 5000 | H11: =IF(B11=0,"",IF(INDEX(Bank!$H:$H,B11)="","",INDEX(Bank!$H:$H,B11))) -> G-2608-0006 | I11: =IF(H11="",0,IFERROR(MATCH(H11,GL!$A:$A,0),0)) -> 9 | J11: =IF(I11=0,"",INDEX(GL!$B:$B,I11)) -> 46244 | K11: =IF(I11=0,"",IF(INDEX(GL!$C:$C,I11)="","",INDEX(GL!$C:$C,I11))) -> Savings x7732 - Transfer in | L11: =IF(I11=0,"",INDEX(GL!$E:$E,I11)) -> 5000 | M11: =IF(OR(B11=0,I11=0),"",ROUND(G11-L11,2)) -> 0 | N11: =IF(A11="","",IF(B11=0,"NOT FOUND: bank ID",IF(I11=0,"NOT FOUND: GL ID",IF(INDEX(GL!$H:$H,I11)<>A11,"BROKEN: GL points elsewhere",IF(OR(INDEX(Bank!$F:$F,B11)<>"Y",INDEX(GL!$F:$F,I11)<>"Y"),"BROKEN: Status not Y","OK"))))) -> OK
A12: B-2608-0007 | B12: =IF(A12="",0,IFERROR(MATCH(A12,Bank!$A:$A,0),0)) -> 8 | C12: =IF(B12=0,"",IF(INDEX(Bank!$G:$G,B12)="","",INDEX(Bank!$G:$G,B12))) -> Exact | D12: =IF(B12=0,"",IF(INDEX(Bank!$J:$J,B12)="","",INDEX(Bank!$J:$J,B12))) -> 1 | E12: =IF(B12=0,"",INDEX(Bank!$B:$B,B12)) -> 46246 | F12: =IF(B12=0,"",IF(INDEX(Bank!$C:$C,B12)="","",INDEX(Bank!$C:$C,B12))) -> ACH DEBIT ROCKY MTN POWER | G12: =IF(B12=0,"",INDEX(Bank!$E:$E,B12)) -> -318.4 | H12: =IF(B12=0,"",IF(INDEX(Bank!$H:$H,B12)="","",INDEX(Bank!$H:$H,B12))) -> G-2608-0007 | I12: =IF(H12="",0,IFERROR(MATCH(H12,GL!$A:$A,0),0)) -> 10 | J12: =IF(I12=0,"",INDEX(GL!$B:$B,I12)) -> 46245 | K12: =IF(I12=0,"",IF(INDEX(GL!$C:$C,I12)="","",INDEX(GL!$C:$C,I12))) -> Rocky Mountain Power - August service | L12: =IF(I12=0,"",INDEX(GL!$E:$E,I12)) -> -318.4 | M12: =IF(OR(B12=0,I12=0),"",ROUND(G12-L12,2)) -> 0 | N12: =IF(A12="","",IF(B12=0,"NOT FOUND: bank ID",IF(I12=0,"NOT FOUND: GL ID",IF(INDEX(GL!$H:$H,I12)<>A12,"BROKEN: GL points elsewhere",IF(OR(INDEX(Bank!$F:$F,B12)<>"Y",INDEX(GL!$F:$F,I12)<>"Y"),"BROKEN: Status not Y","OK"))))) -> OK
A13: B-2608-0008 | B13: =IF(A13="",0,IFERROR(MATCH(A13,Bank!$A:$A,0),0)) -> 9 | C13: =IF(B13=0,"",IF(INDEX(Bank!$G:$G,B13)="","",INDEX(Bank!$G:$G,B13))) -> Exact | D13: =IF(B13=0,"",IF(INDEX(Bank!$J:$J,B13)="","",INDEX(Bank!$J:$J,B13))) -> 1 | E13: =IF(B13=0,"",INDEX(Bank!$B:$B,B13)) -> 46248 | F13: =IF(B13=0,"",IF(INDEX(Bank!$C:$C,B13)="","",INDEX(Bank!$C:$C,B13))) -> CHECK 1038 | G13: =IF(B13=0,"",INDEX(Bank!$E:$E,B13)) -> -2000 | H13: =IF(B13=0,"",IF(INDEX(Bank!$H:$H,B13)="","",INDEX(Bank!$H:$H,B13))) -> G-2607-0019 | I13: =IF(H13="",0,IFERROR(MATCH(H13,GL!$A:$A,0),0)) -> 2 | J13: =IF(I13=0,"",INDEX(GL!$B:$B,I13)) -> 46231 | K13: =IF(I13=0,"",IF(INDEX(GL!$C:$C,I13)="","",INDEX(GL!$C:$C,I13))) -> Canyon Properties - Aug rent | L13: =IF(I13=0,"",INDEX(GL!$E:$E,I13)) -> -2000 | M13: =IF(OR(B13=0,I13=0),"",ROUND(G13-L13,2)) -> 0 | N13: =IF(A13="","",IF(B13=0,"NOT FOUND: bank ID",IF(I13=0,"NOT FOUND: GL ID",IF(INDEX(GL!$H:$H,I13)<>A13,"BROKEN: GL points elsewhere",IF(OR(INDEX(Bank!$F:$F,B13)<>"Y",INDEX(GL!$F:$F,I13)<>"Y"),"BROKEN: Status not Y","OK"))))) -> OK
A14: B-2608-0009 | B14: =IF(A14="",0,IFERROR(MATCH(A14,Bank!$A:$A,0),0)) -> 10 | C14: =IF(B14=0,"",IF(INDEX(Bank!$G:$G,B14)="","",INDEX(Bank!$G:$G,B14))) -> Exact | D14: =IF(B14=0,"",IF(INDEX(Bank!$J:$J,B14)="","",INDEX(Bank!$J:$J,B14))) -> 1 | E14: =IF(B14=0,"",INDEX(Bank!$B:$B,B14)) -> 46251 | F14: =IF(B14=0,"",IF(INDEX(Bank!$C:$C,B14)="","",INDEX(Bank!$C:$C,B14))) -> MOBILE DEPOSIT ALVAREZ | G14: =IF(B14=0,"",INDEX(Bank!$E:$E,B14)) -> 1215.5 | H14: =IF(B14=0,"",IF(INDEX(Bank!$H:$H,B14)="","",INDEX(Bank!$H:$H,B14))) -> G-2608-0009 | I14: =IF(H14="",0,IFERROR(MATCH(H14,GL!$A:$A,0),0)) -> 12 | J14: =IF(I14=0,"",INDEX(GL!$B:$B,I14)) -> 46249 | K14: =IF(I14=0,"",IF(INDEX(GL!$C:$C,I14)="","",INDEX(GL!$C:$C,I14))) -> J. Alvarez - Mobile deposit inv 2291 | L14: =IF(I14=0,"",INDEX(GL!$E:$E,I14)) -> 1215.5 | M14: =IF(OR(B14=0,I14=0),"",ROUND(G14-L14,2)) -> 0 | N14: =IF(A14="","",IF(B14=0,"NOT FOUND: bank ID",IF(I14=0,"NOT FOUND: GL ID",IF(INDEX(GL!$H:$H,I14)<>A14,"BROKEN: GL points elsewhere",IF(OR(INDEX(Bank!$F:$F,B14)<>"Y",INDEX(GL!$F:$F,I14)<>"Y"),"BROKEN: Status not Y","OK"))))) -> OK
A15: B-2608-0011 | B15: =IF(A15="",0,IFERROR(MATCH(A15,Bank!$A:$A,0),0)) -> 12 | C15: =IF(B15=0,"",IF(INDEX(Bank!$G:$G,B15)="","",INDEX(Bank!$G:$G,B15))) -> Exact | D15: =IF(B15=0,"",IF(INDEX(Bank!$J:$J,B15)="","",INDEX(Bank!$J:$J,B15))) -> 1 | E15: =IF(B15=0,"",INDEX(Bank!$B:$B,B15)) -> 46255 | F15: =IF(B15=0,"",IF(INDEX(Bank!$C:$C,B15)="","",INDEX(Bank!$C:$C,B15))) -> CHECK 1046 | G15: =IF(B15=0,"",INDEX(Bank!$E:$E,B15)) -> -743.1 | H15: =IF(B15=0,"",IF(INDEX(Bank!$H:$H,B15)="","",INDEX(Bank!$H:$H,B15))) -> G-2608-0008 | I15: =IF(H15="",0,IFERROR(MATCH(H15,GL!$A:$A,0),0)) -> 11 | J15: =IF(I15=0,"",INDEX(GL!$B:$B,I15)) -> 46246 | K15: =IF(I15=0,"",IF(INDEX(GL!$C:$C,I15)="","",INDEX(GL!$C:$C,I15))) -> Alpine Nursery - Plants | L15: =IF(I15=0,"",INDEX(GL!$E:$E,I15)) -> -743.1 | M15: =IF(OR(B15=0,I15=0),"",ROUND(G15-L15,2)) -> 0 | N15: =IF(A15="","",IF(B15=0,"NOT FOUND: bank ID",IF(I15=0,"NOT FOUND: GL ID",IF(INDEX(GL!$H:$H,I15)<>A15,"BROKEN: GL points elsewhere",IF(OR(INDEX(Bank!$F:$F,B15)<>"Y",INDEX(GL!$F:$F,I15)<>"Y"),"BROKEN: Status not Y","OK"))))) -> OK
A16: B-2608-0012 | B16: =IF(A16="",0,IFERROR(MATCH(A16,Bank!$A:$A,0),0)) -> 13 | C16: =IF(B16=0,"",IF(INDEX(Bank!$G:$G,B16)="","",INDEX(Bank!$G:$G,B16))) -> Exact | D16: =IF(B16=0,"",IF(INDEX(Bank!$J:$J,B16)="","",INDEX(Bank!$J:$J,B16))) -> 1 | E16: =IF(B16=0,"",INDEX(Bank!$B:$B,B16)) -> 46258 | F16: =IF(B16=0,"",IF(INDEX(Bank!$C:$C,B16)="","",INDEX(Bank!$C:$C,B16))) -> ACH CREDIT STRIPE TRANSFER | G16: =IF(B16=0,"",INDEX(Bank!$E:$E,B16)) -> 2847.66 | H16: =IF(B16=0,"",IF(INDEX(Bank!$H:$H,B16)="","",INDEX(Bank!$H:$H,B16))) -> G-2608-0011 | I16: =IF(H16="",0,IFERROR(MATCH(H16,GL!$A:$A,0),0)) -> 14 | J16: =IF(I16=0,"",INDEX(GL!$B:$B,I16)) -> 46258 | K16: =IF(I16=0,"",IF(INDEX(GL!$C:$C,I16)="","",INDEX(GL!$C:$C,I16))) -> Stripe - Payout 8/24 | L16: =IF(I16=0,"",INDEX(GL!$E:$E,I16)) -> 2847.66 | M16: =IF(OR(B16=0,I16=0),"",ROUND(G16-L16,2)) -> 0 | N16: =IF(A16="","",IF(B16=0,"NOT FOUND: bank ID",IF(I16=0,"NOT FOUND: GL ID",IF(INDEX(GL!$H:$H,I16)<>A16,"BROKEN: GL points elsewhere",IF(OR(INDEX(Bank!$F:$F,B16)<>"Y",INDEX(GL!$F:$F,I16)<>"Y"),"BROKEN: Status not Y","OK"))))) -> OK
A17: B-2608-0013 | B17: =IF(A17="",0,IFERROR(MATCH(A17,Bank!$A:$A,0),0)) -> 14 | C17: =IF(B17=0,"",IF(INDEX(Bank!$G:$G,B17)="","",INDEX(Bank!$G:$G,B17))) -> Exact | D17: =IF(B17=0,"",IF(INDEX(Bank!$J:$J,B17)="","",INDEX(Bank!$J:$J,B17))) -> 1 | E17: =IF(B17=0,"",INDEX(Bank!$B:$B,B17)) -> 46260 | F17: =IF(B17=0,"",IF(INDEX(Bank!$C:$C,B17)="","",INDEX(Bank!$C:$C,B17))) -> ACH DEBIT UTAH STATE TAX | G17: =IF(B17=0,"",INDEX(Bank!$E:$E,B17)) -> -1104 | H17: =IF(B17=0,"",IF(INDEX(Bank!$H:$H,B17)="","",INDEX(Bank!$H:$H,B17))) -> G-2608-0012 | I17: =IF(H17="",0,IFERROR(MATCH(H17,GL!$A:$A,0),0)) -> 15 | J17: =IF(I17=0,"",INDEX(GL!$B:$B,I17)) -> 46260 | K17: =IF(I17=0,"",IF(INDEX(GL!$C:$C,I17)="","",INDEX(GL!$C:$C,I17))) -> Utah State Tax Commission - Withholding | L17: =IF(I17=0,"",INDEX(GL!$E:$E,I17)) -> -1104 | M17: =IF(OR(B17=0,I17=0),"",ROUND(G17-L17,2)) -> 0 | N17: =IF(A17="","",IF(B17=0,"NOT FOUND: bank ID",IF(I17=0,"NOT FOUND: GL ID",IF(INDEX(GL!$H:$H,I17)<>A17,"BROKEN: GL points elsewhere",IF(OR(INDEX(Bank!$F:$F,B17)<>"Y",INDEX(GL!$F:$F,I17)<>"Y"),"BROKEN: Status not Y","OK"))))) -> OK
B18: =IF(A18="",0,IFERROR(MATCH(A18,Bank!$A:$A,0),0)) -> 0 | C18: =IF(B18=0,"",IF(INDEX(Bank!$G:$G,B18)="","",INDEX(Bank!$G:$G,B18))) | D18: =IF(B18=0,"",IF(INDEX(Bank!$J:$J,B18)="","",INDEX(Bank!$J:$J,B18))) | E18: =IF(B18=0,"",INDEX(Bank!$B:$B,B18)) | F18: =IF(B18=0,"",IF(INDEX(Bank!$C:$C,B18)="","",INDEX(Bank!$C:$C,B18))) | G18: =IF(B18=0,"",INDEX(Bank!$E:$E,B18)) | H18: =IF(B18=0,"",IF(INDEX(Bank!$H:$H,B18)="","",INDEX(Bank!$H:$H,B18))) | I18: =IF(H18="",0,IFERROR(MATCH(H18,GL!$A:$A,0),0)) -> 0 | J18: =IF(I18=0,"",INDEX(GL!$B:$B,I18)) | K18: =IF(I18=0,"",IF(INDEX(GL!$C:$C,I18)="","",INDEX(GL!$C:$C,I18))) | L18: =IF(I18=0,"",INDEX(GL!$E:$E,I18)) | M18: =IF(OR(B18=0,I18=0),"",ROUND(G18-L18,2)) | N18: =IF(A18="","",IF(B18=0,"NOT FOUND: bank ID",IF(I18=0,"NOT FOUND: GL ID",IF(INDEX(GL!$H:$H,I18)<>A18,"BROKEN: GL points elsewhere",IF(OR(INDEX(Bank!$F:$F,B18)<>"Y",INDEX(GL!$F:$F,I18)<>"Y"),"BROKEN: Status not Y","OK")))))
B19: =IF(A19="",0,IFERROR(MATCH(A19,Bank!$A:$A,0),0)) -> 0 | C19: =IF(B19=0,"",IF(INDEX(Bank!$G:$G,B19)="","",INDEX(Bank!$G:$G,B19))) | D19: =IF(B19=0,"",IF(INDEX(Bank!$J:$J,B19)="","",INDEX(Bank!$J:$J,B19))) | E19: =IF(B19=0,"",INDEX(Bank!$B:$B,B19)) | F19: =IF(B19=0,"",IF(INDEX(Bank!$C:$C,B19)="","",INDEX(Bank!$C:$C,B19))) | G19: =IF(B19=0,"",INDEX(Bank!$E:$E,B19)) | H19: =IF(B19=0,"",IF(INDEX(Bank!$H:$H,B19)="","",INDEX(Bank!$H:$H,B19))) | I19: =IF(H19="",0,IFERROR(MATCH(H19,GL!$A:$A,0),0)) -> 0 | J19: =IF(I19=0,"",INDEX(GL!$B:$B,I19)) | K19: =IF(I19=0,"",IF(INDEX(GL!$C:$C,I19)="","",INDEX(GL!$C:$C,I19))) | L19: =IF(I19=0,"",INDEX(GL!$E:$E,I19)) | M19: =IF(OR(B19=0,I19=0),"",ROUND(G19-L19,2)) | N19: =IF(A19="","",IF(B19=0,"NOT FOUND: bank ID",IF(I19=0,"NOT FOUND: GL ID",IF(INDEX(GL!$H:$H,I19)<>A19,"BROKEN: GL points elsewhere",IF(OR(INDEX(Bank!$F:$F,B19)<>"Y",INDEX(GL!$F:$F,I19)<>"Y"),"BROKEN: Status not Y","OK")))))
B20: =IF(A20="",0,IFERROR(MATCH(A20,Bank!$A:$A,0),0)) -> 0 | C20: =IF(B20=0,"",IF(INDEX(Bank!$G:$G,B20)="","",INDEX(Bank!$G:$G,B20))) | D20: =IF(B20=0,"",IF(INDEX(Bank!$J:$J,B20)="","",INDEX(Bank!$J:$J,B20))) | E20: =IF(B20=0,"",INDEX(Bank!$B:$B,B20)) | F20: =IF(B20=0,"",IF(INDEX(Bank!$C:$C,B20)="","",INDEX(Bank!$C:$C,B20))) | G20: =IF(B20=0,"",INDEX(Bank!$E:$E,B20)) | H20: =IF(B20=0,"",IF(INDEX(Bank!$H:$H,B20)="","",INDEX(Bank!$H:$H,B20))) | I20: =IF(H20="",0,IFERROR(MATCH(H20,GL!$A:$A,0),0)) -> 0 | J20: =IF(I20=0,"",INDEX(GL!$B:$B,I20)) | K20: =IF(I20=0,"",IF(INDEX(GL!$C:$C,I20)="","",INDEX(GL!$C:$C,I20))) | L20: =IF(I20=0,"",INDEX(GL!$E:$E,I20)) | M20: =IF(OR(B20=0,I20=0),"",ROUND(G20-L20,2)) | N20: =IF(A20="","",IF(B20=0,"NOT FOUND: bank ID",IF(I20=0,"NOT FOUND: GL ID",IF(INDEX(GL!$H:$H,I20)<>A20,"BROKEN: GL points elsewhere",IF(OR(INDEX(Bank!$F:$F,B20)<>"Y",INDEX(GL!$F:$F,I20)<>"Y"),"BROKEN: Status not Y","OK")))))
B21: =IF(A21="",0,IFERROR(MATCH(A21,Bank!$A:$A,0),0)) -> 0 | C21: =IF(B21=0,"",IF(INDEX(Bank!$G:$G,B21)="","",INDEX(Bank!$G:$G,B21))) | D21: =IF(B21=0,"",IF(INDEX(Bank!$J:$J,B21)="","",INDEX(Bank!$J:$J,B21))) | E21: =IF(B21=0,"",INDEX(Bank!$B:$B,B21)) | F21: =IF(B21=0,"",IF(INDEX(Bank!$C:$C,B21)="","",INDEX(Bank!$C:$C,B21))) | G21: =IF(B21=0,"",INDEX(Bank!$E:$E,B21)) | H21: =IF(B21=0,"",IF(INDEX(Bank!$H:$H,B21)="","",INDEX(Bank!$H:$H,B21))) | I21: =IF(H21="",0,IFERROR(MATCH(H21,GL!$A:$A,0),0)) -> 0 | J21: =IF(I21=0,"",INDEX(GL!$B:$B,I21)) | K21: =IF(I21=0,"",IF(INDEX(GL!$C:$C,I21)="","",INDEX(GL!$C:$C,I21))) | L21: =IF(I21=0,"",INDEX(GL!$E:$E,I21)) | M21: =IF(OR(B21=0,I21=0),"",ROUND(G21-L21,2)) | N21: =IF(A21="","",IF(B21=0,"NOT FOUND: bank ID",IF(I21=0,"NOT FOUND: GL ID",IF(INDEX(GL!$H:$H,I21)<>A21,"BROKEN: GL points elsewhere",IF(OR(INDEX(Bank!$F:$F,B21)<>"Y",INDEX(GL!$F:$F,I21)<>"Y"),"BROKEN: Status not Y","OK")))))
B22: =IF(A22="",0,IFERROR(MATCH(A22,Bank!$A:$A,0),0)) -> 0 | C22: =IF(B22=0,"",IF(INDEX(Bank!$G:$G,B22)="","",INDEX(Bank!$G:$G,B22))) | D22: =IF(B22=0,"",IF(INDEX(Bank!$J:$J,B22)="","",INDEX(Bank!$J:$J,B22))) | E22: =IF(B22=0,"",INDEX(Bank!$B:$B,B22)) | F22: =IF(B22=0,"",IF(INDEX(Bank!$C:$C,B22)="","",INDEX(Bank!$C:$C,B22))) | G22: =IF(B22=0,"",INDEX(Bank!$E:$E,B22)) | H22: =IF(B22=0,"",IF(INDEX(Bank!$H:$H,B22)="","",INDEX(Bank!$H:$H,B22))) | I22: =IF(H22="",0,IFERROR(MATCH(H22,GL!$A:$A,0),0)) -> 0 | J22: =IF(I22=0,"",INDEX(GL!$B:$B,I22)) | K22: =IF(I22=0,"",IF(INDEX(GL!$C:$C,I22)="","",INDEX(GL!$C:$C,I22))) | L22: =IF(I22=0,"",INDEX(GL!$E:$E,I22)) | M22: =IF(OR(B22=0,I22=0),"",ROUND(G22-L22,2)) | N22: =IF(A22="","",IF(B22=0,"NOT FOUND: bank ID",IF(I22=0,"NOT FOUND: GL ID",IF(INDEX(GL!$H:$H,I22)<>A22,"BROKEN: GL points elsewhere",IF(OR(INDEX(Bank!$F:$F,B22)<>"Y",INDEX(GL!$F:$F,I22)<>"Y"),"BROKEN: Status not Y","OK")))))
B23: =IF(A23="",0,IFERROR(MATCH(A23,Bank!$A:$A,0),0)) -> 0 | C23: =IF(B23=0,"",IF(INDEX(Bank!$G:$G,B23)="","",INDEX(Bank!$G:$G,B23))) | D23: =IF(B23=0,"",IF(INDEX(Bank!$J:$J,B23)="","",INDEX(Bank!$J:$J,B23))) | E23: =IF(B23=0,"",INDEX(Bank!$B:$B,B23)) | F23: =IF(B23=0,"",IF(INDEX(Bank!$C:$C,B23)="","",INDEX(Bank!$C:$C,B23))) | G23: =IF(B23=0,"",INDEX(Bank!$E:$E,B23)) | H23: =IF(B23=0,"",IF(INDEX(Bank!$H:$H,B23)="","",INDEX(Bank!$H:$H,B23))) | I23: =IF(H23="",0,IFERROR(MATCH(H23,GL!$A:$A,0),0)) -> 0 | J23: =IF(I23=0,"",INDEX(GL!$B:$B,I23)) | K23: =IF(I23=0,"",IF(INDEX(GL!$C:$C,I23)="","",INDEX(GL!$C:$C,I23))) | L23: =IF(I23=0,"",INDEX(GL!$E:$E,I23)) | M23: =IF(OR(B23=0,I23=0),"",ROUND(G23-L23,2)) | N23: =IF(A23="","",IF(B23=0,"NOT FOUND: bank ID",IF(I23=0,"NOT FOUND: GL ID",IF(INDEX(GL!$H:$H,I23)<>A23,"BROKEN: GL points elsewhere",IF(OR(INDEX(Bank!$F:$F,B23)<>"Y",INDEX(GL!$F:$F,I23)<>"Y"),"BROKEN: Status not Y","OK")))))
B24: =IF(A24="",0,IFERROR(MATCH(A24,Bank!$A:$A,0),0)) -> 0 | C24: =IF(B24=0,"",IF(INDEX(Bank!$G:$G,B24)="","",INDEX(Bank!$G:$G,B24))) | D24: =IF(B24=0,"",IF(INDEX(Bank!$J:$J,B24)="","",INDEX(Bank!$J:$J,B24))) | E24: =IF(B24=0,"",INDEX(Bank!$B:$B,B24)) | F24: =IF(B24=0,"",IF(INDEX(Bank!$C:$C,B24)="","",INDEX(Bank!$C:$C,B24))) | G24: =IF(B24=0,"",INDEX(Bank!$E:$E,B24)) | H24: =IF(B24=0,"",IF(INDEX(Bank!$H:$H,B24)="","",INDEX(Bank!$H:$H,B24))) | I24: =IF(H24="",0,IFERROR(MATCH(H24,GL!$A:$A,0),0)) -> 0 | J24: =IF(I24=0,"",INDEX(GL!$B:$B,I24)) | K24: =IF(I24=0,"",IF(INDEX(GL!$C:$C,I24)="","",INDEX(GL!$C:$C,I24))) | L24: =IF(I24=0,"",INDEX(GL!$E:$E,I24)) | M24: =IF(OR(B24=0,I24=0),"",ROUND(G24-L24,2)) | N24: =IF(A24="","",IF(B24=0,"NOT FOUND: bank ID",IF(I24=0,"NOT FOUND: GL ID",IF(INDEX(GL!$H:$H,I24)<>A24,"BROKEN: GL points elsewhere",IF(OR(INDEX(Bank!$F:$F,B24)<>"Y",INDEX(GL!$F:$F,I24)<>"Y"),"BROKEN: Status not Y","OK")))))
B25: =IF(A25="",0,IFERROR(MATCH(A25,Bank!$A:$A,0),0)) -> 0 | C25: =IF(B25=0,"",IF(INDEX(Bank!$G:$G,B25)="","",INDEX(Bank!$G:$G,B25))) | D25: =IF(B25=0,"",IF(INDEX(Bank!$J:$J,B25)="","",INDEX(Bank!$J:$J,B25))) | E25: =IF(B25=0,"",INDEX(Bank!$B:$B,B25)) | F25: =IF(B25=0,"",IF(INDEX(Bank!$C:$C,B25)="","",INDEX(Bank!$C:$C,B25))) | G25: =IF(B25=0,"",INDEX(Bank!$E:$E,B25)) | H25: =IF(B25=0,"",IF(INDEX(Bank!$H:$H,B25)="","",INDEX(Bank!$H:$H,B25))) | I25: =IF(H25="",0,IFERROR(MATCH(H25,GL!$A:$A,0),0)) -> 0 | J25: =IF(I25=0,"",INDEX(GL!$B:$B,I25)) | K25: =IF(I25=0,"",IF(INDEX(GL!$C:$C,I25)="","",INDEX(GL!$C:$C,I25))) | L25: =IF(I25=0,"",INDEX(GL!$E:$E,I25)) | M25: =IF(OR(B25=0,I25=0),"",ROUND(G25-L25,2)) | N25: =IF(A25="","",IF(B25=0,"NOT FOUND: bank ID",IF(I25=0,"NOT FOUND: GL ID",IF(INDEX(GL!$H:$H,I25)<>A25,"BROKEN: GL points elsewhere",IF(OR(INDEX(Bank!$F:$F,B25)<>"Y",INDEX(GL!$F:$F,I25)<>"Y"),"BROKEN: Status not Y","OK")))))
B26: =IF(A26="",0,IFERROR(MATCH(A26,Bank!$A:$A,0),0)) -> 0 | C26: =IF(B26=0,"",IF(INDEX(Bank!$G:$G,B26)="","",INDEX(Bank!$G:$G,B26))) | D26: =IF(B26=0,"",IF(INDEX(Bank!$J:$J,B26)="","",INDEX(Bank!$J:$J,B26))) | E26: =IF(B26=0,"",INDEX(Bank!$B:$B,B26)) | F26: =IF(B26=0,"",IF(INDEX(Bank!$C:$C,B26)="","",INDEX(Bank!$C:$C,B26))) | G26: =IF(B26=0,"",INDEX(Bank!$E:$E,B26)) | H26: =IF(B26=0,"",IF(INDEX(Bank!$H:$H,B26)="","",INDEX(Bank!$H:$H,B26))) | I26: =IF(H26="",0,IFERROR(MATCH(H26,GL!$A:$A,0),0)) -> 0 | J26: =IF(I26=0,"",INDEX(GL!$B:$B,I26)) | K26: =IF(I26=0,"",IF(INDEX(GL!$C:$C,I26)="","",INDEX(GL!$C:$C,I26))) | L26: =IF(I26=0,"",INDEX(GL!$E:$E,I26)) | M26: =IF(OR(B26=0,I26=0),"",ROUND(G26-L26,2)) | N26: =IF(A26="","",IF(B26=0,"NOT FOUND: bank ID",IF(I26=0,"NOT FOUND: GL ID",IF(INDEX(GL!$H:$H,I26)<>A26,"BROKEN: GL points elsewhere",IF(OR(INDEX(Bank!$F:$F,B26)<>"Y",INDEX(GL!$F:$F,I26)<>"Y"),"BROKEN: Status not Y","OK")))))
B27: =IF(A27="",0,IFERROR(MATCH(A27,Bank!$A:$A,0),0)) -> 0 | C27: =IF(B27=0,"",IF(INDEX(Bank!$G:$G,B27)="","",INDEX(Bank!$G:$G,B27))) | D27: =IF(B27=0,"",IF(INDEX(Bank!$J:$J,B27)="","",INDEX(Bank!$J:$J,B27))) | E27: =IF(B27=0,"",INDEX(Bank!$B:$B,B27)) | F27: =IF(B27=0,"",IF(INDEX(Bank!$C:$C,B27)="","",INDEX(Bank!$C:$C,B27))) | G27: =IF(B27=0,"",INDEX(Bank!$E:$E,B27)) | H27: =IF(B27=0,"",IF(INDEX(Bank!$H:$H,B27)="","",INDEX(Bank!$H:$H,B27))) | I27: =IF(H27="",0,IFERROR(MATCH(H27,GL!$A:$A,0),0)) -> 0 | J27: =IF(I27=0,"",INDEX(GL!$B:$B,I27)) | K27: =IF(I27=0,"",IF(INDEX(GL!$C:$C,I27)="","",INDEX(GL!$C:$C,I27))) | L27: =IF(I27=0,"",INDEX(GL!$E:$E,I27)) | M27: =IF(OR(B27=0,I27=0),"",ROUND(G27-L27,2)) | N27: =IF(A27="","",IF(B27=0,"NOT FOUND: bank ID",IF(I27=0,"NOT FOUND: GL ID",IF(INDEX(GL!$H:$H,I27)<>A27,"BROKEN: GL points elsewhere",IF(OR(INDEX(Bank!$F:$F,B27)<>"Y",INDEX(GL!$F:$F,I27)<>"Y"),"BROKEN: Status not Y","OK")))))
B28: =IF(A28="",0,IFERROR(MATCH(A28,Bank!$A:$A,0),0)) -> 0 | C28: =IF(B28=0,"",IF(INDEX(Bank!$G:$G,B28)="","",INDEX(Bank!$G:$G,B28))) | D28: =IF(B28=0,"",IF(INDEX(Bank!$J:$J,B28)="","",INDEX(Bank!$J:$J,B28))) | E28: =IF(B28=0,"",INDEX(Bank!$B:$B,B28)) | F28: =IF(B28=0,"",IF(INDEX(Bank!$C:$C,B28)="","",INDEX(Bank!$C:$C,B28))) | G28: =IF(B28=0,"",INDEX(Bank!$E:$E,B28)) | H28: =IF(B28=0,"",IF(INDEX(Bank!$H:$H,B28)="","",INDEX(Bank!$H:$H,B28))) | I28: =IF(H28="",0,IFERROR(MATCH(H28,GL!$A:$A,0),0)) -> 0 | J28: =IF(I28=0,"",INDEX(GL!$B:$B,I28)) | K28: =IF(I28=0,"",IF(INDEX(GL!$C:$C,I28)="","",INDEX(GL!$C:$C,I28))) | L28: =IF(I28=0,"",INDEX(GL!$E:$E,I28)) | M28: =IF(OR(B28=0,I28=0),"",ROUND(G28-L28,2)) | N28: =IF(A28="","",IF(B28=0,"NOT FOUND: bank ID",IF(I28=0,"NOT FOUND: GL ID",IF(INDEX(GL!$H:$H,I28)<>A28,"BROKEN: GL points elsewhere",IF(OR(INDEX(Bank!$F:$F,B28)<>"Y",INDEX(GL!$F:$F,I28)<>"Y"),"BROKEN: Status not Y","OK")))))
B29: =IF(A29="",0,IFERROR(MATCH(A29,Bank!$A:$A,0),0)) -> 0 | C29: =IF(B29=0,"",IF(INDEX(Bank!$G:$G,B29)="","",INDEX(Bank!$G:$G,B29))) | D29: =IF(B29=0,"",IF(INDEX(Bank!$J:$J,B29)="","",INDEX(Bank!$J:$J,B29))) | E29: =IF(B29=0,"",INDEX(Bank!$B:$B,B29)) | F29: =IF(B29=0,"",IF(INDEX(Bank!$C:$C,B29)="","",INDEX(Bank!$C:$C,B29))) | G29: =IF(B29=0,"",INDEX(Bank!$E:$E,B29)) | H29: =IF(B29=0,"",IF(INDEX(Bank!$H:$H,B29)="","",INDEX(Bank!$H:$H,B29))) | I29: =IF(H29="",0,IFERROR(MATCH(H29,GL!$A:$A,0),0)) -> 0 | J29: =IF(I29=0,"",INDEX(GL!$B:$B,I29)) | K29: =IF(I29=0,"",IF(INDEX(GL!$C:$C,I29)="","",INDEX(GL!$C:$C,I29))) | L29: =IF(I29=0,"",INDEX(GL!$E:$E,I29)) | M29: =IF(OR(B29=0,I29=0),"",ROUND(G29-L29,2)) | N29: =IF(A29="","",IF(B29=0,"NOT FOUND: bank ID",IF(I29=0,"NOT FOUND: GL ID",IF(INDEX(GL!$H:$H,I29)<>A29,"BROKEN: GL points elsewhere",IF(OR(INDEX(Bank!$F:$F,B29)<>"Y",INDEX(GL!$F:$F,I29)<>"Y"),"BROKEN: Status not Y","OK")))))
... B2005: =IF(A2005="",0,IFERROR(MATCH(A2005,Bank!$A:$A,0),0)) -> 0 | C2005: =IF(B2005=0,"",IF(INDEX(Bank!$G:$G,B2005)="","",INDEX(Bank!$G:$G,B2005))) | D2005: =IF(B2005=0,"",IF(INDEX(Bank!$J:$J,B2005)="","",INDEX(Bank!$J:$J,B2005))) | E2005: =IF(B2005=0,"",INDEX(Bank!$B:$B,B2005)) | F2005: =IF(B2005=0,"",IF(INDEX(Bank!$C:$C,B2005)="","",INDEX(Bank!$C:$C,B2005))) | G2005: =IF(B2005=0,"",INDEX(Bank!$E:$E,B2005)) | H2005: =IF(B2005=0,"",IF(INDEX(Bank!$H:$H,B2005)="","",INDEX(Bank!$H:$H,B2005))) | I2005: =IF(H2005="",0,IFERROR(MATCH(H2005,GL!$A:$A,0),0)) -> 0 | J2005: =IF(I2005=0,"",INDEX(GL!$B:$B,I2005)) | K2005: =IF(I2005=0,"",IF(INDEX(GL!$C:$C,I2005)="","",INDEX(GL!$C:$C,I2005))) | L2005: =IF(I2005=0,"",INDEX(GL!$E:$E,I2005)) | M2005: =IF(OR(B2005=0,I2005=0),"",ROUND(G2005-L2005,2)) | N2005: =IF(A2005="","",IF(B2005=0,"NOT FOUND: bank ID",IF(I2005=0,"NOT FOUND: GL ID",IF(INDEX(GL!$H:$H,I2005)<>A2005,"BROKEN: GL points elsewhere",IF(OR(INDEX(Bank!$F:$F,B2005)<>"Y",INDEX(GL!$F:$F,I2005)<>"Y"),"BROKEN: Status not Y","OK")))))

Sheet Open Items
A1: Open items (reconciling items)
A2: The skill writes Side + ID for every row without Status = Y. Details are formulas. 'Days Open' is counted to period end.
A3: Deposits in transit | B3: =SUMIFS(G6:G2005,H6:H2005,"Deposit in transit") -> 960 | C3: Outstanding checks / payments | D3: =SUMIFS(G6:G2005,H6:H2005,"Outstanding check / payment") -> -3030.95 | E3: Bank credits not in GL | F3: =SUMIFS(G6:G2005,H6:H2005,"Bank credit not in GL") -> 3.12 | G3: Bank debits not in GL | H3: =SUMIFS(G6:G2005,H6:H2005,"Bank debit not in GL") -> -211.23
A5: Side | B5: ID | C5: row | D5: Date | E5: Description | F5: Ref / Check # | G5: Amount | H5: Category | I5: Days Open | J5: Match Type | K5: Review Note | L5: List Check
A6: GL | B6: G-2607-0022 | C6: =IF(B6="",0,IF(A6="Bank",IFERROR(MATCH(B6,Bank!$A:$A,0),0),IFERROR(MATCH(B6,GL!$A:$A,0),0))) -> 3 | D6: =IF(C6=0,"",IF($A6="Bank",INDEX(Bank!$B:$B,$C6),INDEX(GL!$B:$B,$C6))) -> 46233 | E6: =IF(C6=0,"",IF($A6="Bank",IF(INDEX(Bank!$C:$C,$C6)="","",INDEX(Bank!$C:$C,$C6)),IF(INDEX(GL!$C:$C,$C6)="","",INDEX(GL!$C:$C,$C6)))) -> Wasatch Tree Supply - Saplings | F6: =IF(C6=0,"",IF($A6="Bank",IF(INDEX(Bank!$D:$D,$C6)="","",INDEX(Bank!$D:$D,$C6)),IF(INDEX(GL!$D:$D,$C6)="","",INDEX(GL!$D:$D,$C6)))) -> 1041 | G6: =IF(C6=0,"",IF($A6="Bank",INDEX(Bank!$E:$E,$C6),INDEX(GL!$E:$E,$C6))) -> -455 | H6: =IF(C6=0,"",IF(A6="GL",IF(G6>0,"Deposit in transit","Outstanding check / payment"),IF(G6>0,"Bank credit not in GL","Bank debit not in GL"))) -> Outstanding check / payment | I6: =IF(OR(C6=0,CFG_PeriodEnd=""),"",CFG_PeriodEnd-D6) -> 32 | J6: =IF(C6=0,"",IF($A6="Bank",IF(INDEX(Bank!$G:$G,$C6)="","",INDEX(Bank!$G:$G,$C6)),IF(INDEX(GL!$G:$G,$C6)="","",INDEX(GL!$G:$G,$C6)))) | K6: =IF(C6=0,"",IF($A6="Bank",IF(INDEX(Bank!$I:$I,$C6)="","",INDEX(Bank!$I:$I,$C6)),IF(INDEX(GL!$I:$I,$C6)="","",INDEX(GL!$I:$I,$C6)))) | L6: =IF(B6="","",IF(C6=0,"NOT FOUND",IF(IF($A6="Bank",INDEX(Bank!$F:$F,$C6),INDEX(GL!$F:$F,$C6))="Y","NOW RECONCILED: refresh","OK"))) -> OK
A7: GL | B7: G-2608-0010 | C7: =IF(B7="",0,IF(A7="Bank",IFERROR(MATCH(B7,Bank!$A:$A,0),0),IFERROR(MATCH(B7,GL!$A:$A,0),0))) -> 13 | D7: =IF(C7=0,"",IF($A7="Bank",INDEX(Bank!$B:$B,$C7),INDEX(GL!$B:$B,$C7))) -> 46252 | E7: =IF(C7=0,"",IF($A7="Bank",IF(INDEX(Bank!$C:$C,$C7)="","",INDEX(Bank!$C:$C,$C7)),IF(INDEX(GL!$C:$C,$C7)="","",INDEX(GL!$C:$C,$C7)))) -> Verizon Wireless - August | F7: =IF(C7=0,"",IF($A7="Bank",IF(INDEX(Bank!$D:$D,$C7)="","",INDEX(Bank!$D:$D,$C7)),IF(INDEX(GL!$D:$D,$C7)="","",INDEX(GL!$D:$D,$C7)))) | G7: =IF(C7=0,"",IF($A7="Bank",INDEX(Bank!$E:$E,$C7),INDEX(GL!$E:$E,$C7))) -> -186.2 | H7: =IF(C7=0,"",IF(A7="GL",IF(G7>0,"Deposit in transit","Outstanding check / payment"),IF(G7>0,"Bank credit not in GL","Bank debit not in GL"))) -> Outstanding check / payment | I7: =IF(OR(C7=0,CFG_PeriodEnd=""),"",CFG_PeriodEnd-D7) -> 13 | J7: =IF(C7=0,"",IF($A7="Bank",IF(INDEX(Bank!$G:$G,$C7)="","",INDEX(Bank!$G:$G,$C7)),IF(INDEX(GL!$G:$G,$C7)="","",INDEX(GL!$G:$G,$C7)))) -> Near | K7: =IF(C7=0,"",IF($A7="Bank",IF(INDEX(Bank!$I:$I,$C7)="","",INDEX(Bank!$I:$I,$C7)),IF(INDEX(GL!$I:$I,$C7)="","",INDEX(GL!$I:$I,$C7)))) -> Near match: Bank B-2608-0010 "ACH DEBIT VERIZON WIRELESS" -186.23 (diff 0.03). Not reconciled. | L7: =IF(B7="","",IF(C7=0,"NOT FOUND",IF(IF($A7="Bank",INDEX(Bank!$F:$F,$C7),INDEX(GL!$F:$F,$C7))="Y","NOW RECONCILED: refresh","OK"))) -> OK
A8: GL | B8: G-2608-0013 | C8: =IF(B8="",0,IF(A8="Bank",IFERROR(MATCH(B8,Bank!$A:$A,0),0),IFERROR(MATCH(B8,GL!$A:$A,0),0))) -> 16 | D8: =IF(C8=0,"",IF($A8="Bank",INDEX(Bank!$B:$B,$C8),INDEX(GL!$B:$B,$C8))) -> 46262 | E8: =IF(C8=0,"",IF($A8="Bank",IF(INDEX(Bank!$C:$C,$C8)="","",INDEX(Bank!$C:$C,$C8)),IF(INDEX(GL!$C:$C,$C8)="","",INDEX(GL!$C:$C,$C8)))) -> Canyon Properties - Sep rent | F8: =IF(C8=0,"",IF($A8="Bank",IF(INDEX(Bank!$D:$D,$C8)="","",INDEX(Bank!$D:$D,$C8)),IF(INDEX(GL!$D:$D,$C8)="","",INDEX(GL!$D:$D,$C8)))) -> 1049 | G8: =IF(C8=0,"",IF($A8="Bank",INDEX(Bank!$E:$E,$C8),INDEX(GL!$E:$E,$C8))) -> -2000 | H8: =IF(C8=0,"",IF(A8="GL",IF(G8>0,"Deposit in transit","Outstanding check / payment"),IF(G8>0,"Bank credit not in GL","Bank debit not in GL"))) -> Outstanding check / payment | I8: =IF(OR(C8=0,CFG_PeriodEnd=""),"",CFG_PeriodEnd-D8) -> 3 | J8: =IF(C8=0,"",IF($A8="Bank",IF(INDEX(Bank!$G:$G,$C8)="","",INDEX(Bank!$G:$G,$C8)),IF(INDEX(GL!$G:$G,$C8)="","",INDEX(GL!$G:$G,$C8)))) | K8: =IF(C8=0,"",IF($A8="Bank",IF(INDEX(Bank!$I:$I,$C8)="","",INDEX(Bank!$I:$I,$C8)),IF(INDEX(GL!$I:$I,$C8)="","",INDEX(GL!$I:$I,$C8)))) | L8: =IF(B8="","",IF(C8=0,"NOT FOUND",IF(IF($A8="Bank",INDEX(Bank!$F:$F,$C8),INDEX(GL!$F:$F,$C8))="Y","NOW RECONCILED: refresh","OK"))) -> OK
A9: GL | B9: G-2608-0014 | C9: =IF(B9="",0,IF(A9="Bank",IFERROR(MATCH(B9,Bank!$A:$A,0),0),IFERROR(MATCH(B9,GL!$A:$A,0),0))) -> 17 | D9: =IF(C9=0,"",IF($A9="Bank",INDEX(Bank!$B:$B,$C9),INDEX(GL!$B:$B,$C9))) -> 46263 | E9: =IF(C9=0,"",IF($A9="Bank",IF(INDEX(Bank!$C:$C,$C9)="","",INDEX(Bank!$C:$C,$C9)),IF(INDEX(GL!$C:$C,$C9)="","",INDEX(GL!$C:$C,$C9)))) -> Peak Fuel - Fuel | F9: =IF(C9=0,"",IF($A9="Bank",IF(INDEX(Bank!$D:$D,$C9)="","",INDEX(Bank!$D:$D,$C9)),IF(INDEX(GL!$D:$D,$C9)="","",INDEX(GL!$D:$D,$C9)))) -> 1050 | G9: =IF(C9=0,"",IF($A9="Bank",INDEX(Bank!$E:$E,$C9),INDEX(GL!$E:$E,$C9))) -> -389.75 | H9: =IF(C9=0,"",IF(A9="GL",IF(G9>0,"Deposit in transit","Outstanding check / payment"),IF(G9>0,"Bank credit not in GL","Bank debit not in GL"))) -> Outstanding check / payment | I9: =IF(OR(C9=0,CFG_PeriodEnd=""),"",CFG_PeriodEnd-D9) -> 2 | J9: =IF(C9=0,"",IF($A9="Bank",IF(INDEX(Bank!$G:$G,$C9)="","",INDEX(Bank!$G:$G,$C9)),IF(INDEX(GL!$G:$G,$C9)="","",INDEX(GL!$G:$G,$C9)))) | K9: =IF(C9=0,"",IF($A9="Bank",IF(INDEX(Bank!$I:$I,$C9)="","",INDEX(Bank!$I:$I,$C9)),IF(INDEX(GL!$I:$I,$C9)="","",INDEX(GL!$I:$I,$C9)))) | L9: =IF(B9="","",IF(C9=0,"NOT FOUND",IF(IF($A9="Bank",INDEX(Bank!$F:$F,$C9),INDEX(GL!$F:$F,$C9))="Y","NOW RECONCILED: refresh","OK"))) -> OK
A10: GL | B10: G-2608-0015 | C10: =IF(B10="",0,IF(A10="Bank",IFERROR(MATCH(B10,Bank!$A:$A,0),0),IFERROR(MATCH(B10,GL!$A:$A,0),0))) -> 18 | D10: =IF(C10=0,"",IF($A10="Bank",INDEX(Bank!$B:$B,$C10),INDEX(GL!$B:$B,$C10))) -> 46265 | E10: =IF(C10=0,"",IF($A10="Bank",IF(INDEX(Bank!$C:$C,$C10)="","",INDEX(Bank!$C:$C,$C10)),IF(INDEX(GL!$C:$C,$C10)="","",INDEX(GL!$C:$C,$C10)))) -> Birch Lane Homes - Customer payment | F10: =IF(C10=0,"",IF($A10="Bank",IF(INDEX(Bank!$D:$D,$C10)="","",INDEX(Bank!$D:$D,$C10)),IF(INDEX(GL!$D:$D,$C10)="","",INDEX(GL!$D:$D,$C10)))) | G10: =IF(C10=0,"",IF($A10="Bank",INDEX(Bank!$E:$E,$C10),INDEX(GL!$E:$E,$C10))) -> 960 | H10: =IF(C10=0,"",IF(A10="GL",IF(G10>0,"Deposit in transit","Outstanding check / payment"),IF(G10>0,"Bank credit not in GL","Bank debit not in GL"))) -> Deposit in transit | I10: =IF(OR(C10=0,CFG_PeriodEnd=""),"",CFG_PeriodEnd-D10) -> 0 | J10: =IF(C10=0,"",IF($A10="Bank",IF(INDEX(Bank!$G:$G,$C10)="","",INDEX(Bank!$G:$G,$C10)),IF(INDEX(GL!$G:$G,$C10)="","",INDEX(GL!$G:$G,$C10)))) | K10: =IF(C10=0,"",IF($A10="Bank",IF(INDEX(Bank!$I:$I,$C10)="","",INDEX(Bank!$I:$I,$C10)),IF(INDEX(GL!$I:$I,$C10)="","",INDEX(GL!$I:$I,$C10)))) | L10: =IF(B10="","",IF(C10=0,"NOT FOUND",IF(IF($A10="Bank",INDEX(Bank!$F:$F,$C10),INDEX(GL!$F:$F,$C10))="Y","NOW RECONCILED: refresh","OK"))) -> OK
A11: Bank | B11: B-2608-0010 | C11: =IF(B11="",0,IF(A11="Bank",IFERROR(MATCH(B11,Bank!$A:$A,0),0),IFERROR(MATCH(B11,GL!$A:$A,0),0))) -> 11 | D11: =IF(C11=0,"",IF($A11="Bank",INDEX(Bank!$B:$B,$C11),INDEX(GL!$B:$B,$C11))) -> 46253 | E11: =IF(C11=0,"",IF($A11="Bank",IF(INDEX(Bank!$C:$C,$C11)="","",INDEX(Bank!$C:$C,$C11)),IF(INDEX(GL!$C:$C,$C11)="","",INDEX(GL!$C:$C,$C11)))) -> ACH DEBIT VERIZON WIRELESS | F11: =IF(C11=0,"",IF($A11="Bank",IF(INDEX(Bank!$D:$D,$C11)="","",INDEX(Bank!$D:$D,$C11)),IF(INDEX(GL!$D:$D,$C11)="","",INDEX(GL!$D:$D,$C11)))) | G11: =IF(C11=0,"",IF($A11="Bank",INDEX(Bank!$E:$E,$C11),INDEX(GL!$E:$E,$C11))) -> -186.23 | H11: =IF(C11=0,"",IF(A11="GL",IF(G11>0,"Deposit in transit","Outstanding check / payment"),IF(G11>0,"Bank credit not in GL","Bank debit not in GL"))) -> Bank debit not in GL | I11: =IF(OR(C11=0,CFG_PeriodEnd=""),"",CFG_PeriodEnd-D11) -> 12 | J11: =IF(C11=0,"",IF($A11="Bank",IF(INDEX(Bank!$G:$G,$C11)="","",INDEX(Bank!$G:$G,$C11)),IF(INDEX(GL!$G:$G,$C11)="","",INDEX(GL!$G:$G,$C11)))) -> Near | K11: =IF(C11=0,"",IF($A11="Bank",IF(INDEX(Bank!$I:$I,$C11)="","",INDEX(Bank!$I:$I,$C11)),IF(INDEX(GL!$I:$I,$C11)="","",INDEX(GL!$I:$I,$C11)))) -> Near match: GL G-2608-0010 "Verizon Wireless - August" -186.20 (diff 0.03). Not reconciled. | L11: =IF(B11="","",IF(C11=0,"NOT FOUND",IF(IF($A11="Bank",INDEX(Bank!$F:$F,$C11),INDEX(GL!$F:$F,$C11))="Y","NOW RECONCILED: refresh","OK"))) -> OK
A12: Bank | B12: B-2608-0014 | C12: =IF(B12="",0,IF(A12="Bank",IFERROR(MATCH(B12,Bank!$A:$A,0),0),IFERROR(MATCH(B12,GL!$A:$A,0),0))) -> 15 | D12: =IF(C12=0,"",IF($A12="Bank",INDEX(Bank!$B:$B,$C12),INDEX(GL!$B:$B,$C12))) -> 46263 | E12: =IF(C12=0,"",IF($A12="Bank",IF(INDEX(Bank!$C:$C,$C12)="","",INDEX(Bank!$C:$C,$C12)),IF(INDEX(GL!$C:$C,$C12)="","",INDEX(GL!$C:$C,$C12)))) -> SERVICE CHARGE | F12: =IF(C12=0,"",IF($A12="Bank",IF(INDEX(Bank!$D:$D,$C12)="","",INDEX(Bank!$D:$D,$C12)),IF(INDEX(GL!$D:$D,$C12)="","",INDEX(GL!$D:$D,$C12)))) | G12: =IF(C12=0,"",IF($A12="Bank",INDEX(Bank!$E:$E,$C12),INDEX(GL!$E:$E,$C12))) -> -25 | H12: =IF(C12=0,"",IF(A12="GL",IF(G12>0,"Deposit in transit","Outstanding check / payment"),IF(G12>0,"Bank credit not in GL","Bank debit not in GL"))) -> Bank debit not in GL | I12: =IF(OR(C12=0,CFG_PeriodEnd=""),"",CFG_PeriodEnd-D12) -> 2 | J12: =IF(C12=0,"",IF($A12="Bank",IF(INDEX(Bank!$G:$G,$C12)="","",INDEX(Bank!$G:$G,$C12)),IF(INDEX(GL!$G:$G,$C12)="","",INDEX(GL!$G:$G,$C12)))) | K12: =IF(C12=0,"",IF($A12="Bank",IF(INDEX(Bank!$I:$I,$C12)="","",INDEX(Bank!$I:$I,$C12)),IF(INDEX(GL!$I:$I,$C12)="","",INDEX(GL!$I:$I,$C12)))) | L12: =IF(B12="","",IF(C12=0,"NOT FOUND",IF(IF($A12="Bank",INDEX(Bank!$F:$F,$C12),INDEX(GL!$F:$F,$C12))="Y","NOW RECONCILED: refresh","OK"))) -> OK
A13: Bank | B13: B-2608-0015 | C13: =IF(B13="",0,IF(A13="Bank",IFERROR(MATCH(B13,Bank!$A:$A,0),0),IFERROR(MATCH(B13,GL!$A:$A,0),0))) -> 16 | D13: =IF(C13=0,"",IF($A13="Bank",INDEX(Bank!$B:$B,$C13),INDEX(GL!$B:$B,$C13))) -> 46265 | E13: =IF(C13=0,"",IF($A13="Bank",IF(INDEX(Bank!$C:$C,$C13)="","",INDEX(Bank!$C:$C,$C13)),IF(INDEX(GL!$C:$C,$C13)="","",INDEX(GL!$C:$C,$C13)))) -> INTEREST PAYMENT | F13: =IF(C13=0,"",IF($A13="Bank",IF(INDEX(Bank!$D:$D,$C13)="","",INDEX(Bank!$D:$D,$C13)),IF(INDEX(GL!$D:$D,$C13)="","",INDEX(GL!$D:$D,$C13)))) | G13: =IF(C13=0,"",IF($A13="Bank",INDEX(Bank!$E:$E,$C13),INDEX(GL!$E:$E,$C13))) -> 3.12 | H13: =IF(C13=0,"",IF(A13="GL",IF(G13>0,"Deposit in transit","Outstanding check / payment"),IF(G13>0,"Bank credit not in GL","Bank debit not in GL"))) -> Bank credit not in GL | I13: =IF(OR(C13=0,CFG_PeriodEnd=""),"",CFG_PeriodEnd-D13) -> 0 | J13: =IF(C13=0,"",IF($A13="Bank",IF(INDEX(Bank!$G:$G,$C13)="","",INDEX(Bank!$G:$G,$C13)),IF(INDEX(GL!$G:$G,$C13)="","",INDEX(GL!$G:$G,$C13)))) | K13: =IF(C13=0,"",IF($A13="Bank",IF(INDEX(Bank!$I:$I,$C13)="","",INDEX(Bank!$I:$I,$C13)),IF(INDEX(GL!$I:$I,$C13)="","",INDEX(GL!$I:$I,$C13)))) | L13: =IF(B13="","",IF(C13=0,"NOT FOUND",IF(IF($A13="Bank",INDEX(Bank!$F:$F,$C13),INDEX(GL!$F:$F,$C13))="Y","NOW RECONCILED: refresh","OK"))) -> OK
C14: =IF(B14="",0,IF(A14="Bank",IFERROR(MATCH(B14,Bank!$A:$A,0),0),IFERROR(MATCH(B14,GL!$A:$A,0),0))) -> 0 | D14: =IF(C14=0,"",IF($A14="Bank",INDEX(Bank!$B:$B,$C14),INDEX(GL!$B:$B,$C14))) | E14: =IF(C14=0,"",IF($A14="Bank",IF(INDEX(Bank!$C:$C,$C14)="","",INDEX(Bank!$C:$C,$C14)),IF(INDEX(GL!$C:$C,$C14)="","",INDEX(GL!$C:$C,$C14)))) | F14: =IF(C14=0,"",IF($A14="Bank",IF(INDEX(Bank!$D:$D,$C14)="","",INDEX(Bank!$D:$D,$C14)),IF(INDEX(GL!$D:$D,$C14)="","",INDEX(GL!$D:$D,$C14)))) | G14: =IF(C14=0,"",IF($A14="Bank",INDEX(Bank!$E:$E,$C14),INDEX(GL!$E:$E,$C14))) | H14: =IF(C14=0,"",IF(A14="GL",IF(G14>0,"Deposit in transit","Outstanding check / payment"),IF(G14>0,"Bank credit not in GL","Bank debit not in GL"))) | I14: =IF(OR(C14=0,CFG_PeriodEnd=""),"",CFG_PeriodEnd-D14) | J14: =IF(C14=0,"",IF($A14="Bank",IF(INDEX(Bank!$G:$G,$C14)="","",INDEX(Bank!$G:$G,$C14)),IF(INDEX(GL!$G:$G,$C14)="","",INDEX(GL!$G:$G,$C14)))) | K14: =IF(C14=0,"",IF($A14="Bank",IF(INDEX(Bank!$I:$I,$C14)="","",INDEX(Bank!$I:$I,$C14)),IF(INDEX(GL!$I:$I,$C14)="","",INDEX(GL!$I:$I,$C14)))) | L14: =IF(B14="","",IF(C14=0,"NOT FOUND",IF(IF($A14="Bank",INDEX(Bank!$F:$F,$C14),INDEX(GL!$F:$F,$C14))="Y","NOW RECONCILED: refresh","OK")))
C15: =IF(B15="",0,IF(A15="Bank",IFERROR(MATCH(B15,Bank!$A:$A,0),0),IFERROR(MATCH(B15,GL!$A:$A,0),0))) -> 0 | D15: =IF(C15=0,"",IF($A15="Bank",INDEX(Bank!$B:$B,$C15),INDEX(GL!$B:$B,$C15))) | E15: =IF(C15=0,"",IF($A15="Bank",IF(INDEX(Bank!$C:$C,$C15)="","",INDEX(Bank!$C:$C,$C15)),IF(INDEX(GL!$C:$C,$C15)="","",INDEX(GL!$C:$C,$C15)))) | F15: =IF(C15=0,"",IF($A15="Bank",IF(INDEX(Bank!$D:$D,$C15)="","",INDEX(Bank!$D:$D,$C15)),IF(INDEX(GL!$D:$D,$C15)="","",INDEX(GL!$D:$D,$C15)))) | G15: =IF(C15=0,"",IF($A15="Bank",INDEX(Bank!$E:$E,$C15),INDEX(GL!$E:$E,$C15))) | H15: =IF(C15=0,"",IF(A15="GL",IF(G15>0,"Deposit in transit","Outstanding check / payment"),IF(G15>0,"Bank credit not in GL","Bank debit not in GL"))) | I15: =IF(OR(C15=0,CFG_PeriodEnd=""),"",CFG_PeriodEnd-D15) | J15: =IF(C15=0,"",IF($A15="Bank",IF(INDEX(Bank!$G:$G,$C15)="","",INDEX(Bank!$G:$G,$C15)),IF(INDEX(GL!$G:$G,$C15)="","",INDEX(GL!$G:$G,$C15)))) | K15: =IF(C15=0,"",IF($A15="Bank",IF(INDEX(Bank!$I:$I,$C15)="","",INDEX(Bank!$I:$I,$C15)),IF(INDEX(GL!$I:$I,$C15)="","",INDEX(GL!$I:$I,$C15)))) | L15: =IF(B15="","",IF(C15=0,"NOT FOUND",IF(IF($A15="Bank",INDEX(Bank!$F:$F,$C15),INDEX(GL!$F:$F,$C15))="Y","NOW RECONCILED: refresh","OK")))
C16: =IF(B16="",0,IF(A16="Bank",IFERROR(MATCH(B16,Bank!$A:$A,0),0),IFERROR(MATCH(B16,GL!$A:$A,0),0))) -> 0 | D16: =IF(C16=0,"",IF($A16="Bank",INDEX(Bank!$B:$B,$C16),INDEX(GL!$B:$B,$C16))) | E16: =IF(C16=0,"",IF($A16="Bank",IF(INDEX(Bank!$C:$C,$C16)="","",INDEX(Bank!$C:$C,$C16)),IF(INDEX(GL!$C:$C,$C16)="","",INDEX(GL!$C:$C,$C16)))) | F16: =IF(C16=0,"",IF($A16="Bank",IF(INDEX(Bank!$D:$D,$C16)="","",INDEX(Bank!$D:$D,$C16)),IF(INDEX(GL!$D:$D,$C16)="","",INDEX(GL!$D:$D,$C16)))) | G16: =IF(C16=0,"",IF($A16="Bank",INDEX(Bank!$E:$E,$C16),INDEX(GL!$E:$E,$C16))) | H16: =IF(C16=0,"",IF(A16="GL",IF(G16>0,"Deposit in transit","Outstanding check / payment"),IF(G16>0,"Bank credit not in GL","Bank debit not in GL"))) | I16: =IF(OR(C16=0,CFG_PeriodEnd=""),"",CFG_PeriodEnd-D16) | J16: =IF(C16=0,"",IF($A16="Bank",IF(INDEX(Bank!$G:$G,$C16)="","",INDEX(Bank!$G:$G,$C16)),IF(INDEX(GL!$G:$G,$C16)="","",INDEX(GL!$G:$G,$C16)))) | K16: =IF(C16=0,"",IF($A16="Bank",IF(INDEX(Bank!$I:$I,$C16)="","",INDEX(Bank!$I:$I,$C16)),IF(INDEX(GL!$I:$I,$C16)="","",INDEX(GL!$I:$I,$C16)))) | L16: =IF(B16="","",IF(C16=0,"NOT FOUND",IF(IF($A16="Bank",INDEX(Bank!$F:$F,$C16),INDEX(GL!$F:$F,$C16))="Y","NOW RECONCILED: refresh","OK")))
C17: =IF(B17="",0,IF(A17="Bank",IFERROR(MATCH(B17,Bank!$A:$A,0),0),IFERROR(MATCH(B17,GL!$A:$A,0),0))) -> 0 | D17: =IF(C17=0,"",IF($A17="Bank",INDEX(Bank!$B:$B,$C17),INDEX(GL!$B:$B,$C17))) | E17: =IF(C17=0,"",IF($A17="Bank",IF(INDEX(Bank!$C:$C,$C17)="","",INDEX(Bank!$C:$C,$C17)),IF(INDEX(GL!$C:$C,$C17)="","",INDEX(GL!$C:$C,$C17)))) | F17: =IF(C17=0,"",IF($A17="Bank",IF(INDEX(Bank!$D:$D,$C17)="","",INDEX(Bank!$D:$D,$C17)),IF(INDEX(GL!$D:$D,$C17)="","",INDEX(GL!$D:$D,$C17)))) | G17: =IF(C17=0,"",IF($A17="Bank",INDEX(Bank!$E:$E,$C17),INDEX(GL!$E:$E,$C17))) | H17: =IF(C17=0,"",IF(A17="GL",IF(G17>0,"Deposit in transit","Outstanding check / payment"),IF(G17>0,"Bank credit not in GL","Bank debit not in GL"))) | I17: =IF(OR(C17=0,CFG_PeriodEnd=""),"",CFG_PeriodEnd-D17) | J17: =IF(C17=0,"",IF($A17="Bank",IF(INDEX(Bank!$G:$G,$C17)="","",INDEX(Bank!$G:$G,$C17)),IF(INDEX(GL!$G:$G,$C17)="","",INDEX(GL!$G:$G,$C17)))) | K17: =IF(C17=0,"",IF($A17="Bank",IF(INDEX(Bank!$I:$I,$C17)="","",INDEX(Bank!$I:$I,$C17)),IF(INDEX(GL!$I:$I,$C17)="","",INDEX(GL!$I:$I,$C17)))) | L17: =IF(B17="","",IF(C17=0,"NOT FOUND",IF(IF($A17="Bank",INDEX(Bank!$F:$F,$C17),INDEX(GL!$F:$F,$C17))="Y","NOW RECONCILED: refresh","OK")))
C18: =IF(B18="",0,IF(A18="Bank",IFERROR(MATCH(B18,Bank!$A:$A,0),0),IFERROR(MATCH(B18,GL!$A:$A,0),0))) -> 0 | D18: =IF(C18=0,"",IF($A18="Bank",INDEX(Bank!$B:$B,$C18),INDEX(GL!$B:$B,$C18))) | E18: =IF(C18=0,"",IF($A18="Bank",IF(INDEX(Bank!$C:$C,$C18)="","",INDEX(Bank!$C:$C,$C18)),IF(INDEX(GL!$C:$C,$C18)="","",INDEX(GL!$C:$C,$C18)))) | F18: =IF(C18=0,"",IF($A18="Bank",IF(INDEX(Bank!$D:$D,$C18)="","",INDEX(Bank!$D:$D,$C18)),IF(INDEX(GL!$D:$D,$C18)="","",INDEX(GL!$D:$D,$C18)))) | G18: =IF(C18=0,"",IF($A18="Bank",INDEX(Bank!$E:$E,$C18),INDEX(GL!$E:$E,$C18))) | H18: =IF(C18=0,"",IF(A18="GL",IF(G18>0,"Deposit in transit","Outstanding check / payment"),IF(G18>0,"Bank credit not in GL","Bank debit not in GL"))) | I18: =IF(OR(C18=0,CFG_PeriodEnd=""),"",CFG_PeriodEnd-D18) | J18: =IF(C18=0,"",IF($A18="Bank",IF(INDEX(Bank!$G:$G,$C18)="","",INDEX(Bank!$G:$G,$C18)),IF(INDEX(GL!$G:$G,$C18)="","",INDEX(GL!$G:$G,$C18)))) | K18: =IF(C18=0,"",IF($A18="Bank",IF(INDEX(Bank!$I:$I,$C18)="","",INDEX(Bank!$I:$I,$C18)),IF(INDEX(GL!$I:$I,$C18)="","",INDEX(GL!$I:$I,$C18)))) | L18: =IF(B18="","",IF(C18=0,"NOT FOUND",IF(IF($A18="Bank",INDEX(Bank!$F:$F,$C18),INDEX(GL!$F:$F,$C18))="Y","NOW RECONCILED: refresh","OK")))
